Workbook

Sheet Anleitung
A1: Protokoll Testdurchläufe AsiMiNu
A3: Zweck | B3: Hier werden alle Testdurchläufe alt (Excel und E-Mail) gegen neu (AsiMiNu-System) festgehalten. Die Testfälle stehen im Dokument „Testfälle Testdurchläufe.docx“.
A4: Gelbe Zellen | B4: Nur gelbe Zellen ausfüllen. Graue Zellen rechnen selbst und werden nicht überschrieben.
A5: Blattfolge | B5: 1. Testdaten: vor dem Termin Testtag, Standorte und Monatsvolumen eintragen. 2. Beobachtung TSM: vor dem Termin 5 bis 10 echte Übertragungen ins TSM beobachten (nur Kürzel, Zeiten, Anzahlen). 3. Durchläufe: eine Zeile je Testfall, Weg und Durchgang (schon vorbelegt). 4. Fehler: eine Zeile je Fehler. 5. Datenqualität: nach jedem Durchlauf Feld für Feld Soll gegen Ist (Ist: Template bzw. Anfrage im System). 6. Befragung: Antworten aus dem Fragebogen. 7. Auswertung: rechnet alles für Abschnitt 6.3 zusammen.
A6: Zeiten | B6: Uhrzeiten als hh:mm:ss eintragen (Stoppuhr oder Uhr am Laptop). Die Dauer in Minuten rechnet das Blatt. Eingabe: vom Öffnen des Templates bzw. Formulars bis zum Klick auf Senden bzw. Absenden. Prüfung: vom Öffnen der Mail bzw. Anfrage bis zur Entscheidung (validiert, abgelehnt, Rückfrage gestellt). Ohne Abtippen. Rückfrage: Dauer der Klärung zwischen CC und GU in Minuten, direkt als Zahl. Abtippen ins TSM: wird nicht im Test gemessen, sondern vor dem Termin im Betrieb beobachtet (Blatt Beobachtung TSM).
A7: Wartezeiten | B7: Zeit, in der niemand arbeitet (z. B. bis zum nächsten Übertragungslauf), zählt nicht mit.
A8: Beispiel Durchläufe | B8: Nr 7 | A | TF 2 | alt | 1 | P1 | P3 | 21.10.2026 | 10:02:10 | 10:06:45 | (4,6) | 10:07:00 | 10:12:30 | (5,5) | ja | 3,2 | … | übertragen | ja | … | nein | | | CC hat die fehlende Nummer bei der Prüfung bemerkt
A9: Beispiel Fehler | B9: Nr 1 | Durchlauf 7 | (TF 2) | (alt) | Telefonnummer Techniker vor Ort fehlt | Vollständigkeit | ja | CC bei Prüfung | nein | Rückfrage per Telefon
A10: Beispiel Datenqualität | B10: Durchlauf 7 | Techniker vor Ort Telefon | Soll +49 160 7654321 | Ist +49 160 7654321 | vorhanden ja | korrekt ja
A11: Personen | B11: Nur Kürzel (P1, P2 …) eintragen, keine Namen. Die Zuordnung Kürzel zu Person bleibt außerhalb dieser Datei.
A12: Eingriffe | B12: Muss der Versuchsleiter helfen oder etwas erklären, in der Spalte „Eingriff Versuchsleiter“ ja eintragen und in der Bemerkung beschreiben.
A14: Legende
A15: eingeben | B15: Zelle von Hand ausfüllen
A16: berechnet | B16: Formel, nicht überschreiben

Sheet Testdaten
A1: Testdaten (vor dem Termin ausfüllen)
A3: Testtag (erster Termin) | B3: 46314 | D3: Datum des ersten Testtermins. Alle Datumswerte unten rechnen sich daraus.
A4: Standort U1 (unkritisch, TF 1, TF 4, TF 5) | B4: 120990497 | D4: Standortnummer, die die Automatik mit Konfiguration A zulässt. Muss in der Testumgebung vorhanden sein. Drei verschiedene Standorte, weil die Anomalieerkennung TF 1 bis TF 3 an einem Standort als Stückelung bzw. Häufung werten würde.
A5: Standort U2 (unkritisch, TF 2) | B5: 120990539 | D5: Standortnummer, die die Automatik mit Konfiguration A zulässt. Muss in der Testumgebung vorhanden sein.
A6: Standort U3 (unkritisch, TF 3) | B6: 121990047 | D6: Standortnummer, die die Automatik mit Konfiguration A zulässt. Muss in der Testumgebung vorhanden sein.
A7: Standort K (kritisch) | B7: 120990686 | D7: Standortnummer mit Risikomerkmal, z. B. Alleinversorger oder Kategorie 3.
A8: AsiMiNu-Anfragen pro Monat | B8: 256 | D8: Angabe der BayFu (Frage 4 der Mail). Für die Hochrechnung.
A9: Standortnummer mit Zahlendreher (TF 3) | B9: =IF(LEN(B6)<2,"",LEFT(B6,LEN(B6)-2)&MID(B6,LEN(B6),1)&MID(B6,LEN(B6)-1,1)) -> 121990074 | D9: Letzte zwei Ziffern von Standort U3 vertauscht. Nur für die Betreffzeile. Ergibt in der Testumgebung einen anderen, gültigen Standort.
A11: Gemeinsame Angaben aller Auftragskarten
A12: Auftraggeber | B12: Vodafone / Vantage
A13: Generalunternehmer | B13: Muster Bau GmbH
A14: Baukoordinator Name | B14: Max Mustermann
A15: Baukoordinator Telefon | B15: +49 171 1234567
A16: Techniker vor Ort Name | B16: Erika Musterfrau
A17: Techniker vor Ort Telefon | B17: +49 160 7654321
A18: Tätigkeit | B18: ASI Abschaltung
A19: Tätigkeit Details | B19: Antennentausch am Mast
A21: Zeiträume je Testfall (rechnen sich aus dem Testtag)
A22: Testfall | B22: Beginn | C22: Ende | D22: Hinweis
A23: TF 1 | B23: =WORKDAY($B$3,5)+TIME(8,0,0) -> 46321.333 | C23: =WORKDAY($B$3,5)+TIME(9,0,0) -> 46321.375 | D23: Werktag, 60 Minuten SA-Dauer, Vorlauf über 72 Stunden
A24: TF 2 | B24: =WORKDAY($B$3,6)+TIME(8,0,0) -> 46322.333 | C24: =WORKDAY($B$3,6)+TIME(9,0,0) -> 46322.375 | D24: wie TF 1, einen Werktag später
A25: TF 3 | B25: =WORKDAY($B$3,7)+TIME(8,0,0) -> 46323.333 | C25: =WORKDAY($B$3,7)+TIME(9,0,0) -> 46323.375 | D25: wie TF 1, zwei Werktage später
A26: TF 4 ursprünglich | B26: =($B$3-WEEKDAY($B$3,2)+22)+TIME(8,0,0) -> 46335.333 | C26: =($B$3-WEEKDAY($B$3,2)+22)+2+TIME(9,0,0) -> 46337.375 | D26: drei Ausfalltage Mo bis Mi, vorab eingereicht
A27: TF 4 korrigiert (Soll) | B27: =($B$3-WEEKDAY($B$3,2)+22)+TIME(8,0,0) -> 46335.333 | C27: =($B$3-WEEKDAY($B$3,2)+22)+TIME(9,0,0) -> 46335.375 | D27: nur noch der Montag
A28: TF 5 ursprünglich | B28: =($B$3-WEEKDAY($B$3,2)+29)+TIME(8,0,0) -> 46342.333 | C28: =($B$3-WEEKDAY($B$3,2)+29)+2+TIME(9,0,0) -> 46344.375 | D28: Mo bis Mi, vorab eingereicht und übertragen
A29: TF 5 korrigiert (Soll) | B29: =($B$3-WEEKDAY($B$3,2)+29)+1+TIME(8,0,0) -> 46343.333 | C29: =($B$3-WEEKDAY($B$3,2)+29)+3+TIME(9,0,0) -> 46345.375 | D29: Di bis Do, überschneidet sich mit dem ursprünglichen Zeitraum
A30: TF 6 | B30: =($B$3-WEEKDAY($B$3,2)+22)+TIME(8,0,0) -> 46335.333 | C30: =($B$3-WEEKDAY($B$3,2)+22)+9+TIME(17,0,0) -> 46344.708 | D30: zehn Kalendertage Mo bis Mi, Begründung nötig
A32: Begründung TF 6 | B32: Austausch der gesamten Antennenanlage, Kran nur in diesem Zeitraum verfügbar

Sheet Beobachtung TSM
A1: Nr | B1: Datum | C1: CC-Person | D1: Ausfalltage der Anfrage | E1: Abtippen Start | F1: Abtippen Ende | G1: Abtippen [min] | H1: Abweichung TSM gegen Template? | I1: Art der Abweichung (ohne echte Daten) | J1: Bemerkung
A2: 1 | G2: =IF(OR(E2="",F2=""),"",ROUND((F2-E2)*1440,1))
A3: 2 | G3: =IF(OR(E3="",F3=""),"",ROUND((F3-E3)*1440,1))
A4: 3 | G4: =IF(OR(E4="",F4=""),"",ROUND((F4-E4)*1440,1))
A5: 4 | G5: =IF(OR(E5="",F5=""),"",ROUND((F5-E5)*1440,1))
A6: 5 | G6: =IF(OR(E6="",F6=""),"",ROUND((F6-E6)*1440,1))
A7: 6 | G7: =IF(OR(E7="",F7=""),"",ROUND((F7-E7)*1440,1))
A8: 7 | G8: =IF(OR(E8="",F8=""),"",ROUND((F8-E8)*1440,1))
A9: 8 | G9: =IF(OR(E9="",F9=""),"",ROUND((F9-E9)*1440,1))
A10: 9 | G10: =IF(OR(E10="",F10=""),"",ROUND((F10-E10)*1440,1))
A11: 10 | G11: =IF(OR(E11="",F11=""),"",ROUND((F11-E11)*1440,1))
A12: 11 | G12: =IF(OR(E12="",F12=""),"",ROUND((F12-E12)*1440,1))
A13: 12 | G13: =IF(OR(E13="",F13=""),"",ROUND((F13-E13)*1440,1))
... A16: 15 | G16: =IF(OR(E16="",F16=""),"",ROUND((F16-E16)*1440,1))
A18: Vor dem Termin bei 5 bis 10 echten Anfragen zusehen, wie die CC-Person die Angaben aus dem Template ins TSM überträgt. Zeit vom ersten bis zum letzten Feld. Nur Kürzel, Uhrzeiten und Anzahlen eintragen, keine Standortnummern oder Namen.

Sheet Durchläufe
A1: Nr | B1: Durch-gang | C1: Testfall | D1: Weg | E1: Reihen-folge | F1: GU-Person | G1: CC-Person | H1: Datum | I1: Eingabe Start | J1: Eingabe Ende | K1: Eingabe [min] | L1: Prüfung Start | M1: Prüfung Ende | N1: Prüfung [min] | O1: Rückfrage nötig? | P1: Rückfrage [min] | Q1: Gesamt [min] | R1: Ergebnis | S1: Konsistent? | T1: Fehler im End-ergebnis | U1: Eingriff Versuchs-leiter | V1: DB: Eingereicht | W1: DB: Validiert | X1: Bemerkung | Y1: h Eingabe alt | Z1: h Eingabe neu | AA1: h Prüfung alt | AB1: h Prüfung neu | AC1: h Gesamt alt | AD1: h Gesamt neu
A2: 1 | B2: A | C2: TF 1 | D2: alt | E2: 1 | K2: =IF(OR(I2="",J2=""),"",ROUND((J2-I2)*1440,1)) | N2: =IF(OR(L2="",M2=""),"",ROUND((M2-L2)*1440,1)) | Q2: =IF(K2="","",SUM(K2,N2,P2)) | T2: =IF(K2="","",IF(COUNTIFS(Fehler!$B$2:$B$200,A2,Fehler!$I$2:$I$200,"ja")>0,"ja","nein")) | Y2: =IF(AND(D2="alt",K2<>""),K2,"") | Z2: =IF(AND(D2="neu",K2<>""),K2,"") | AA2: =IF(AND(D2="alt",K2<>""),SUM(N2,P2),"") | AB2: =IF(AND(D2="neu",K2<>""),SUM(N2,P2),"") | AC2: =IF(AND(D2="alt",K2<>""),Q2,"") | AD2: =IF(AND(D2="neu",K2<>""),SUM(K2,N2,P2),"")
A3: 2 | B3: A | C3: TF 1 | D3: neu | E3: 2 | K3: =IF(OR(I3="",J3=""),"",ROUND((J3-I3)*1440,1)) | N3: =IF(OR(L3="",M3=""),"",ROUND((M3-L3)*1440,1)) | Q3: =IF(K3="","",SUM(K3,N3,P3)) | T3: =IF(K3="","",IF(COUNTIFS(Fehler!$B$2:$B$200,A3,Fehler!$I$2:$I$200,"ja")>0,"ja","nein")) | Y3: =IF(AND(D3="alt",K3<>""),K3,"") | Z3: =IF(AND(D3="neu",K3<>""),K3,"") | AA3: =IF(AND(D3="alt",K3<>""),SUM(N3,P3),"") | AB3: =IF(AND(D3="neu",K3<>""),SUM(N3,P3),"") | AC3: =IF(AND(D3="alt",K3<>""),Q3,"") | AD3: =IF(AND(D3="neu",K3<>""),SUM(K3,N3,P3),"")
A4: 3 | B4: A | C4: TF 2 | D4: neu | E4: 1 | K4: =IF(OR(I4="",J4=""),"",ROUND((J4-I4)*1440,1)) | N4: =IF(OR(L4="",M4=""),"",ROUND((M4-L4)*1440,1)) | Q4: =IF(K4="","",SUM(K4,N4,P4)) | T4: =IF(K4="","",IF(COUNTIFS(Fehler!$B$2:$B$200,A4,Fehler!$I$2:$I$200,"ja")>0,"ja","nein")) | Y4: =IF(AND(D4="alt",K4<>""),K4,"") | Z4: =IF(AND(D4="neu",K4<>""),K4,"") | AA4: =IF(AND(D4="alt",K4<>""),SUM(N4,P4),"") | AB4: =IF(AND(D4="neu",K4<>""),SUM(N4,P4),"") | AC4: =IF(AND(D4="alt",K4<>""),Q4,"") | AD4: =IF(AND(D4="neu",K4<>""),SUM(K4,N4,P4),"")
A5: 4 | B5: A | C5: TF 2 | D5: alt | E5: 2 | K5: =IF(OR(I5="",J5=""),"",ROUND((J5-I5)*1440,1)) | N5: =IF(OR(L5="",M5=""),"",ROUND((M5-L5)*1440,1)) | Q5: =IF(K5="","",SUM(K5,N5,P5)) | T5: =IF(K5="","",IF(COUNTIFS(Fehler!$B$2:$B$200,A5,Fehler!$I$2:$I$200,"ja")>0,"ja","nein")) | Y5: =IF(AND(D5="alt",K5<>""),K5,"") | Z5: =IF(AND(D5="neu",K5<>""),K5,"") | AA5: =IF(AND(D5="alt",K5<>""),SUM(N5,P5),"") | AB5: =IF(AND(D5="neu",K5<>""),SUM(N5,P5),"") | AC5: =IF(AND(D5="alt",K5<>""),Q5,"") | AD5: =IF(AND(D5="neu",K5<>""),SUM(K5,N5,P5),"")
A6: 5 | B6: A | C6: TF 3 | D6: alt | E6: 1 | K6: =IF(OR(I6="",J6=""),"",ROUND((J6-I6)*1440,1)) | N6: =IF(OR(L6="",M6=""),"",ROUND((M6-L6)*1440,1)) | Q6: =IF(K6="","",SUM(K6,N6,P6)) | T6: =IF(K6="","",IF(COUNTIFS(Fehler!$B$2:$B$200,A6,Fehler!$I$2:$I$200,"ja")>0,"ja","nein")) | Y6: =IF(AND(D6="alt",K6<>""),K6,"") | Z6: =IF(AND(D6="neu",K6<>""),K6,"") | AA6: =IF(AND(D6="alt",K6<>""),SUM(N6,P6),"") | AB6: =IF(AND(D6="neu",K6<>""),SUM(N6,P6),"") | AC6: =IF(AND(D6="alt",K6<>""),Q6,"") | AD6: =IF(AND(D6="neu",K6<>""),SUM(K6,N6,P6),"")
A7: 6 | B7: A | C7: TF 3 | D7: neu | E7: 2 | K7: =IF(OR(I7="",J7=""),"",ROUND((J7-I7)*1440,1)) | N7: =IF(OR(L7="",M7=""),"",ROUND((M7-L7)*1440,1)) | Q7: =IF(K7="","",SUM(K7,N7,P7)) | T7: =IF(K7="","",IF(COUNTIFS(Fehler!$B$2:$B$200,A7,Fehler!$I$2:$I$200,"ja")>0,"ja","nein")) | Y7: =IF(AND(D7="alt",K7<>""),K7,"") | Z7: =IF(AND(D7="neu",K7<>""),K7,"") | AA7: =IF(AND(D7="alt",K7<>""),SUM(N7,P7),"") | AB7: =IF(AND(D7="neu",K7<>""),SUM(N7,P7),"") | AC7: =IF(AND(D7="alt",K7<>""),Q7,"") | AD7: =IF(AND(D7="neu",K7<>""),SUM(K7,N7,P7),"")
A8: 7 | B8: A | C8: TF 4 | D8: neu | E8: 1 | K8: =IF(OR(I8="",J8=""),"",ROUND((J8-I8)*1440,1)) | N8: =IF(OR(L8="",M8=""),"",ROUND((M8-L8)*1440,1)) | Q8: =IF(K8="","",SUM(K8,N8,P8)) | T8: =IF(K8="","",IF(COUNTIFS(Fehler!$B$2:$B$200,A8,Fehler!$I$2:$I$200,"ja")>0,"ja","nein")) | Y8: =IF(AND(D8="alt",K8<>""),K8,"") | Z8: =IF(AND(D8="neu",K8<>""),K8,"") | AA8: =IF(AND(D8="alt",K8<>""),SUM(N8,P8),"") | AB8: =IF(AND(D8="neu",K8<>""),SUM(N8,P8),"") | AC8: =IF(AND(D8="alt",K8<>""),Q8,"") | AD8: =IF(AND(D8="neu",K8<>""),SUM(K8,N8,P8),"")
A9: 8 | B9: A | C9: TF 4 | D9: alt | E9: 2 | K9: =IF(OR(I9="",J9=""),"",ROUND((J9-I9)*1440,1)) | N9: =IF(OR(L9="",M9=""),"",ROUND((M9-L9)*1440,1)) | Q9: =IF(K9="","",SUM(K9,N9,P9)) | T9: =IF(K9="","",IF(COUNTIFS(Fehler!$B$2:$B$200,A9,Fehler!$I$2:$I$200,"ja")>0,"ja","nein")) | Y9: =IF(AND(D9="alt",K9<>""),K9,"") | Z9: =IF(AND(D9="neu",K9<>""),K9,"") | AA9: =IF(AND(D9="alt",K9<>""),SUM(N9,P9),"") | AB9: =IF(AND(D9="neu",K9<>""),SUM(N9,P9),"") | AC9: =IF(AND(D9="alt",K9<>""),Q9,"") | AD9: =IF(AND(D9="neu",K9<>""),SUM(K9,N9,P9),"")
A10: 9 | B10: A | C10: TF 5 | D10: alt | E10: 1 | K10: =IF(OR(I10="",J10=""),"",ROUND((J10-I10)*1440,1)) | N10: =IF(OR(L10="",M10=""),"",ROUND((M10-L10)*1440,1)) | Q10: =IF(K10="","",SUM(K10,N10,P10)) | T10: =IF(K10="","",IF(COUNTIFS(Fehler!$B$2:$B$200,A10,Fehler!$I$2:$I$200,"ja")>0,"ja","nein")) | Y10: =IF(AND(D10="alt",K10<>""),K10,"") | Z10: =IF(AND(D10="neu",K10<>""),K10,"") | AA10: =IF(AND(D10="alt",K10<>""),SUM(N10,P10),"") | AB10: =IF(AND(D10="neu",K10<>""),SUM(N10,P10),"") | AC10: =IF(AND(D10="alt",K10<>""),Q10,"") | AD10: =IF(AND(D10="neu",K10<>""),SUM(K10,N10,P10),"")
A11: 10 | B11: A | C11: TF 5 | D11: neu | E11: 2 | K11: =IF(OR(I11="",J11=""),"",ROUND((J11-I11)*1440,1)) | N11: =IF(OR(L11="",M11=""),"",ROUND((M11-L11)*1440,1)) | Q11: =IF(K11="","",SUM(K11,N11,P11)) | T11: =IF(K11="","",IF(COUNTIFS(Fehler!$B$2:$B$200,A11,Fehler!$I$2:$I$200,"ja")>0,"ja","nein")) | Y11: =IF(AND(D11="alt",K11<>""),K11,"") | Z11: =IF(AND(D11="neu",K11<>""),K11,"") | AA11: =IF(AND(D11="alt",K11<>""),SUM(N11,P11),"") | AB11: =IF(AND(D11="neu",K11<>""),SUM(N11,P11),"") | AC11: =IF(AND(D11="alt",K11<>""),Q11,"") | AD11: =IF(AND(D11="neu",K11<>""),SUM(K11,N11,P11),"")
A12: 11 | B12: A | C12: TF 6 | D12: neu | E12: 1 | K12: =IF(OR(I12="",J12=""),"",ROUND((J12-I12)*1440,1)) | N12: =IF(OR(L12="",M12=""),"",ROUND((M12-L12)*1440,1)) | Q12: =IF(K12="","",SUM(K12,N12,P12)) | T12: =IF(K12="","",IF(COUNTIFS(Fehler!$B$2:$B$200,A12,Fehler!$I$2:$I$200,"ja")>0,"ja","nein")) | Y12: =IF(AND(D12="alt",K12<>""),K12,"") | Z12: =IF(AND(D12="neu",K12<>""),K12,"") | AA12: =IF(AND(D12="alt",K12<>""),SUM(N12,P12),"") | AB12: =IF(AND(D12="neu",K12<>""),SUM(N12,P12),"") | AC12: =IF(AND(D12="alt",K12<>""),Q12,"") | AD12: =IF(AND(D12="neu",K12<>""),SUM(K12,N12,P12),"")
A13: 12 | B13: A | C13: TF 6 | D13: alt | E13: 2 | K13: =IF(OR(I13="",J13=""),"",ROUND((J13-I13)*1440,1)) | N13: =IF(OR(L13="",M13=""),"",ROUND((M13-L13)*1440,1)) | Q13: =IF(K13="","",SUM(K13,N13,P13)) | T13: =IF(K13="","",IF(COUNTIFS(Fehler!$B$2:$B$200,A13,Fehler!$I$2:$I$200,"ja")>0,"ja","nein")) | Y13: =IF(AND(D13="alt",K13<>""),K13,"") | Z13: =IF(AND(D13="neu",K13<>""),K13,"") | AA13: =IF(AND(D13="alt",K13<>""),SUM(N13,P13),"") | AB13: =IF(AND(D13="neu",K13<>""),SUM(N13,P13),"") | AC13: =IF(AND(D13="alt",K13<>""),Q13,"") | AD13: =IF(AND(D13="neu",K13<>""),SUM(K13,N13,P13),"")
... A25: 24 | B25: B | C25: TF 6 | D25: neu | E25: 2 | K25: =IF(OR(I25="",J25=""),"",ROUND((J25-I25)*1440,1)) | N25: =IF(OR(L25="",M25=""),"",ROUND((M25-L25)*1440,1)) | Q25: =IF(K25="","",SUM(K25,N25,P25)) | T25: =IF(K25="","",IF(COUNTIFS(Fehler!$B$2:$B$200,A25,Fehler!$I$2:$I$200,"ja")>0,"ja","nein")) | Y25: =IF(AND(D25="alt",K25<>""),K25,"") | Z25: =IF(AND(D25="neu",K25<>""),K25,"") | AA25: =IF(AND(D25="alt",K25<>""),SUM(N25,P25),"") | AB25: =IF(AND(D25="neu",K25<>""),SUM(N25,P25),"") | AC25: =IF(AND(D25="alt",K25<>""),Q25,"") | AD25: =IF(AND(D25="neu",K25<>""),SUM(K25,N25,P25),"")

Sheet Fehler
A1: Nr | B1: Durchlauf-Nr | C1: Testfall | D1: Weg | E1: Fehler (Beschreibung) | F1: Dimension | G1: Eingebaut? | H1: Wo aufgefallen | I1: Im Endergebnis? | J1: Bemerkung
A2: 1 | C2: =IF(B2="","",IFERROR(INDEX(Durchläufe!$C$2:$C$25,MATCH(B2,Durchläufe!$A$2:$A$25,0)),"?")) | D2: =IF(B2="","",IFERROR(INDEX(Durchläufe!$D$2:$D$25,MATCH(B2,Durchläufe!$A$2:$A$25,0)),"?"))
A3: 2 | C3: =IF(B3="","",IFERROR(INDEX(Durchläufe!$C$2:$C$25,MATCH(B3,Durchläufe!$A$2:$A$25,0)),"?")) | D3: =IF(B3="","",IFERROR(INDEX(Durchläufe!$D$2:$D$25,MATCH(B3,Durchläufe!$A$2:$A$25,0)),"?"))
A4: 3 | C4: =IF(B4="","",IFERROR(INDEX(Durchläufe!$C$2:$C$25,MATCH(B4,Durchläufe!$A$2:$A$25,0)),"?")) | D4: =IF(B4="","",IFERROR(INDEX(Durchläufe!$D$2:$D$25,MATCH(B4,Durchläufe!$A$2:$A$25,0)),"?"))
A5: 4 | C5: =IF(B5="","",IFERROR(INDEX(Durchläufe!$C$2:$C$25,MATCH(B5,Durchläufe!$A$2:$A$25,0)),"?")) | D5: =IF(B5="","",IFERROR(INDEX(Durchläufe!$D$2:$D$25,MATCH(B5,Durchläufe!$A$2:$A$25,0)),"?"))
A6: 5 | C6: =IF(B6="","",IFERROR(INDEX(Durchläufe!$C$2:$C$25,MATCH(B6,Durchläufe!$A$2:$A$25,0)),"?")) | D6: =IF(B6="","",IFERROR(INDEX(Durchläufe!$D$2:$D$25,MATCH(B6,Durchläufe!$A$2:$A$25,0)),"?"))
A7: 6 | C7: =IF(B7="","",IFERROR(INDEX(Durchläufe!$C$2:$C$25,MATCH(B7,Durchläufe!$A$2:$A$25,0)),"?")) | D7: =IF(B7="","",IFERROR(INDEX(Durchläufe!$D$2:$D$25,MATCH(B7,Durchläufe!$A$2:$A$25,0)),"?"))
A8: 7 | C8: =IF(B8="","",IFERROR(INDEX(Durchläufe!$C$2:$C$25,MATCH(B8,Durchläufe!$A$2:$A$25,0)),"?")) | D8: =IF(B8="","",IFERROR(INDEX(Durchläufe!$D$2:$D$25,MATCH(B8,Durchläufe!$A$2:$A$25,0)),"?"))
A9: 8 | C9: =IF(B9="","",IFERROR(INDEX(Durchläufe!$C$2:$C$25,MATCH(B9,Durchläufe!$A$2:$A$25,0)),"?")) | D9: =IF(B9="","",IFERROR(INDEX(Durchläufe!$D$2:$D$25,MATCH(B9,Durchläufe!$A$2:$A$25,0)),"?"))
A10: 9 | C10: =IF(B10="","",IFERROR(INDEX(Durchläufe!$C$2:$C$25,MATCH(B10,Durchläufe!$A$2:$A$25,0)),"?")) | D10: =IF(B10="","",IFERROR(INDEX(Durchläufe!$D$2:$D$25,MATCH(B10,Durchläufe!$A$2:$A$25,0)),"?"))
A11: 10 | C11: =IF(B11="","",IFERROR(INDEX(Durchläufe!$C$2:$C$25,MATCH(B11,Durchläufe!$A$2:$A$25,0)),"?")) | D11: =IF(B11="","",IFERROR(INDEX(Durchläufe!$D$2:$D$25,MATCH(B11,Durchläufe!$A$2:$A$25,0)),"?"))
A12: 11 | C12: =IF(B12="","",IFERROR(INDEX(Durchläufe!$C$2:$C$25,MATCH(B12,Durchläufe!$A$2:$A$25,0)),"?")) | D12: =IF(B12="","",IFERROR(INDEX(Durchläufe!$D$2:$D$25,MATCH(B12,Durchläufe!$A$2:$A$25,0)),"?"))
A13: 12 | C13: =IF(B13="","",IFERROR(INDEX(Durchläufe!$C$2:$C$25,MATCH(B13,Durchläufe!$A$2:$A$25,0)),"?")) | D13: =IF(B13="","",IFERROR(INDEX(Durchläufe!$D$2:$D$25,MATCH(B13,Durchläufe!$A$2:$A$25,0)),"?"))
... A199: 198 | C199: =IF(B199="","",IFERROR(INDEX(Durchläufe!$C$2:$C$25,MATCH(B199,Durchläufe!$A$2:$A$25,0)),"?")) | D199: =IF(B199="","",IFERROR(INDEX(Durchläufe!$D$2:$D$25,MATCH(B199,Durchläufe!$A$2:$A$25,0)),"?"))

Sheet Datenqualität
A1: Durchlauf-Nr | B1: Testfall | C1: Weg | D1: Feld | E1: Soll | F1: Ist | G1: Vorhanden? | H1: Korrekt? | I1: Bemerkung
A2: 1 | B2: TF 1 | C2: alt | D2: Standortnummer | E2: =Testdaten!$B$4 -> 120990497
A3: 1 | B3: TF 1 | C3: alt | D3: Auftraggeber | E3: =Testdaten!$B$12 -> Vodafone / Vantage
A4: 1 | B4: TF 1 | C4: alt | D4: Baukoordinator Name | E4: =Testdaten!$B$14 -> Max Mustermann
A5: 1 | B5: TF 1 | C5: alt | D5: Baukoordinator Telefon | E5: =Testdaten!$B$15 -> +49 171 1234567
A6: 1 | B6: TF 1 | C6: alt | D6: Techniker vor Ort Name | E6: =Testdaten!$B$16 -> Erika Musterfrau
A7: 1 | B7: TF 1 | C7: alt | D7: Techniker vor Ort Telefon | E7: =Testdaten!$B$17 -> +49 160 7654321
A8: 1 | B8: TF 1 | C8: alt | D8: Tätigkeit | E8: =Testdaten!$B$18 -> ASI Abschaltung
A9: 1 | B9: TF 1 | C9: alt | D9: Beginn | E9: =Testdaten!$B$23 -> 46321.333
A10: 1 | B10: TF 1 | C10: alt | D10: Ende | E10: =Testdaten!$C$23 -> 46321.375
A11: 1 | B11: TF 1 | C11: alt | D11: Begründung | E11: –
A12: 2 | B12: TF 1 | C12: neu | D12: Standortnummer | E12: =Testdaten!$B$4 -> 120990497
A13: 2 | B13: TF 1 | C13: neu | D13: Auftraggeber | E13: =Testdaten!$B$12 -> Vodafone / Vantage
A14: 2 | B14: TF 1 | C14: neu | D14: Baukoordinator Name | E14: =Testdaten!$B$14 -> Max Mustermann
A15: 2 | B15: TF 1 | C15: neu | D15: Baukoordinator Telefon | E15: =Testdaten!$B$15 -> +49 171 1234567
A16: 2 | B16: TF 1 | C16: neu | D16: Techniker vor Ort Name | E16: =Testdaten!$B$16 -> Erika Musterfrau
A17: 2 | B17: TF 1 | C17: neu | D17: Techniker vor Ort Telefon | E17: =Testdaten!$B$17 -> +49 160 7654321
A18: 2 | B18: TF 1 | C18: neu | D18: Tätigkeit | E18: =Testdaten!$B$18 -> ASI Abschaltung
A19: 2 | B19: TF 1 | C19: neu | D19: Beginn | E19: =Testdaten!$B$23 -> 46321.333
A20: 2 | B20: TF 1 | C20: neu | D20: Ende | E20: =Testdaten!$C$23 -> 46321.375
A21: 2 | B21: TF 1 | C21: neu | D21: Begründung | E21: –
A22: 3 | B22: TF 2 | C22: neu | D22: Standortnummer | E22: =Testdaten!$B$5
A23: 3 | B23: TF 2 | C23: neu | D23: Auftraggeber | E23: =Testdaten!$B$12 -> Vodafone / Vantage
A24: 3 | B24: TF 2 | C24: neu | D24: Baukoordinator Name | E24: =Testdaten!$B$14 -> Max Mustermann
A25: 3 | B25: TF 2 | C25: neu | D25: Baukoordinator Telefon | E25: =Testdaten!$B$15 -> +49 171 1234567
A26: 3 | B26: TF 2 | C26: neu | D26: Techniker vor Ort Name | E26: =Testdaten!$B$16 -> Erika Musterfrau
A27: 3 | B27: TF 2 | C27: neu | D27: Techniker vor Ort Telefon | E27: =Testdaten!$B$17 -> +49 160 7654321
A28: 3 | B28: TF 2 | C28: neu | D28: Tätigkeit | E28: =Testdaten!$B$18 -> ASI Abschaltung
A29: 3 | B29: TF 2 | C29: neu | D29: Beginn | E29: =Testdaten!$B$24 -> 46322.333
A30: 3 | B30: TF 2 | C30: neu | D30: Ende | E30: =Testdaten!$C$24 -> 46322.375
A31: 3 | B31: TF 2 | C31: neu | D31: Begründung | E31: –
A32: 4 | B32: TF 2 | C32: alt | D32: Standortnummer | E32: =Testdaten!$B$5
A33: 4 | B33: TF 2 | C33: alt | D33: Auftraggeber | E33: =Testdaten!$B$12 -> Vodafone / Vantage
A34: 4 | B34: TF 2 | C34: alt | D34: Baukoordinator Name | E34: =Testdaten!$B$14 -> Max Mustermann
A35: 4 | B35: TF 2 | C35: alt | D35: Baukoordinator Telefon | E35: =Testdaten!$B$15 -> +49 171 1234567
A36: 4 | B36: TF 2 | C36: alt | D36: Techniker vor Ort Name | E36: =Testdaten!$B$16 -> Erika Musterfrau
A37: 4 | B37: TF 2 | C37: alt | D37: Techniker vor Ort Telefon | E37: =Testdaten!$B$17 -> +49 160 7654321
A38: 4 | B38: TF 2 | C38: alt | D38: Tätigkeit | E38: =Testdaten!$B$18 -> ASI Abschaltung
A39: 4 | B39: TF 2 | C39: alt | D39: Beginn | E39: =Testdaten!$B$24 -> 46322.333
A40: 4 | B40: TF 2 | C40: alt | D40: Ende | E40: =Testdaten!$C$24 -> 46322.375
...

Sheet Befragung
A1: Person | B1: Rolle | C1: Nr | D1: Aussage | E1: Alt (1–5) | F1: Neu (1–5) | G1: Kommentar
A2: P1 | C2: 1 | D2: Ich konnte die Anfrage ohne Umwege erfassen bzw. prüfen.
A3: P1 | C3: 2 | D3: Ich wusste jederzeit, was als Nächstes zu tun ist.
A4: P1 | C4: 3 | D4: Das Werkzeug hat sich so verhalten, wie ich es erwartet habe.
A5: P1 | C5: 4 | D5: Fehler in den Angaben wurden rechtzeitig und verständlich angezeigt.
A6: P1 | C6: 5 | D6: Ich hatte den Ablauf jederzeit unter Kontrolle.
A7: P1 | C7: 6 | D7: Ich kann nachvollziehen, was mit einer Anfrage passiert ist.
A8: P1 | C8: 7 | D8: Mit diesem Weg würde ich im Alltag gern arbeiten.
A9: P1 | C9: 8 | D9: Offene Frage: Was ist dir besonders aufgefallen? (Antwort in Spalte Kommentar) | E9: – | F9: –
A10: P2 | C10: 1 | D10: Ich konnte die Anfrage ohne Umwege erfassen bzw. prüfen.
A11: P2 | C11: 2 | D11: Ich wusste jederzeit, was als Nächstes zu tun ist.
A12: P2 | C12: 3 | D12: Das Werkzeug hat sich so verhalten, wie ich es erwartet habe.
A13: P2 | C13: 4 | D13: Fehler in den Angaben wurden rechtzeitig und verständlich angezeigt.
A14: P2 | C14: 5 | D14: Ich hatte den Ablauf jederzeit unter Kontrolle.
A15: P2 | C15: 6 | D15: Ich kann nachvollziehen, was mit einer Anfrage passiert ist.
A16: P2 | C16: 7 | D16: Mit diesem Weg würde ich im Alltag gern arbeiten.
A17: P2 | C17: 8 | D17: Offene Frage: Was ist dir besonders aufgefallen? (Antwort in Spalte Kommentar) | E17: – | F17: –
A18: P3 | C18: 1 | D18: Ich konnte die Anfrage ohne Umwege erfassen bzw. prüfen.
A19: P3 | C19: 2 | D19: Ich wusste jederzeit, was als Nächstes zu tun ist.
A20: P3 | C20: 3 | D20: Das Werkzeug hat sich so verhalten, wie ich es erwartet habe.
A21: P3 | C21: 4 | D21: Fehler in den Angaben wurden rechtzeitig und verständlich angezeigt.
A22: P3 | C22: 5 | D22: Ich hatte den Ablauf jederzeit unter Kontrolle.
A23: P3 | C23: 6 | D23: Ich kann nachvollziehen, was mit einer Anfrage passiert ist.
A24: P3 | C24: 7 | D24: Mit diesem Weg würde ich im Alltag gern arbeiten.
A25: P3 | C25: 8 | D25: Offene Frage: Was ist dir besonders aufgefallen? (Antwort in Spalte Kommentar) | E25: – | F25: –
A26: P4 | C26: 1 | D26: Ich konnte die Anfrage ohne Umwege erfassen bzw. prüfen.
A27: P4 | C27: 2 | D27: Ich wusste jederzeit, was als Nächstes zu tun ist.
A28: P4 | C28: 3 | D28: Das Werkzeug hat sich so verhalten, wie ich es erwartet habe.
A29: P4 | C29: 4 | D29: Fehler in den Angaben wurden rechtzeitig und verständlich angezeigt.
A30: P4 | C30: 5 | D30: Ich hatte den Ablauf jederzeit unter Kontrolle.
A31: P4 | C31: 6 | D31: Ich kann nachvollziehen, was mit einer Anfrage passiert ist.
A32: P4 | C32: 7 | D32: Mit diesem Weg würde ich im Alltag gern arbeiten.
A33: P4 | C33: 8 | D33: Offene Frage: Was ist dir besonders aufgefallen? (Antwort in Spalte Kommentar) | E33: – | F33: –
A34: P5 | C34: 1 | D34: Ich konnte die Anfrage ohne Umwege erfassen bzw. prüfen.
A35: P5 | C35: 2 | D35: Ich wusste jederzeit, was als Nächstes zu tun ist.
A36: P5 | C36: 3 | D36: Das Werkzeug hat sich so verhalten, wie ich es erwartet habe.
A37: P5 | C37: 4 | D37: Fehler in den Angaben wurden rechtzeitig und verständlich angezeigt.
A38: P5 | C38: 5 | D38: Ich hatte den Ablauf jederzeit unter Kontrolle.
A39: P5 | C39: 6 | D39: Ich kann nachvollziehen, was mit einer Anfrage passiert ist.
A40: P5 | C40: 7 | D40: Mit diesem Weg würde ich im Alltag gern arbeiten.
...

Sheet Auswertung
A1: Auswertung für Abschnitt 6.3
A2: Alles berechnet. Bei kleiner Stichprobe Median statt Mittelwert. Das Abtippen ins TSM wird nicht im Test gemessen, sondern im Betrieb beobachtet (Blatt Beobachtung TSM). „alt“ und „neu heute“ enthalten diese Abtippzeit, „neu mit Schnittstelle“ nicht.
A4: 1. Bearbeitungszeit (Median in Minuten)
A5: Kennzahl | B5: alt | C5: neu (mit Schnittstelle) | D5: neu heute | E5: Veränderung alt → neu
A6: Eingabe GU | B6: =IFERROR(MEDIAN(Durchläufe!$Y$2:$Y$25),"–") -> – | C6: =IFERROR(MEDIAN(Durchläufe!$Z$2:$Z$25),"–") -> – | D6: =C6 -> – | E6: =IFERROR((C6-B6)/B6,"–") -> –
A7: Prüfung CC inkl. Rückfrage | B7: =IFERROR(MEDIAN(Durchläufe!$AA$2:$AA$25),"–") -> – | C7: =IFERROR(MEDIAN(Durchläufe!$AB$2:$AB$25),"–") -> – | D7: =C7 -> – | E7: =IFERROR((C7-B7)/B7,"–") -> –
A8: Abtippen ins TSM | B8: =IFERROR(MEDIAN('Beobachtung TSM'!$G$2:$G$16),"–") -> – | C8: 0 | D8: =B8 -> – | E8: =IFERROR((C8-B8)/B8,"–") -> – | F8: im Betrieb beobachtet (Blatt Beobachtung TSM), mit Schnittstelle entfällt das Abtippen
A9: Gesamt je Anfrage | B9: =IFERROR(MEDIAN(Durchläufe!$AC$2:$AC$25)+IF(ISNUMBER(B8),B8,0),"–") -> – | C9: =IFERROR(MEDIAN(Durchläufe!$AD$2:$AD$25),"–") -> – | D9: =IFERROR(C9+IF(ISNUMBER(D8),D8,0),"–") -> – | E9: =IFERROR((C9-B9)/B9,"–") -> –
A10: Anzahl ausgewertete Durchläufe | B10: =COUNT(Durchläufe!$AC$2:$AC$25) -> 0 | C10: =COUNT(Durchläufe!$AD$2:$AD$25) -> 0 | D10: =COUNT('Beobachtung TSM'!$G$2:$G$16) -> 0 | F10: Spalte „neu heute“: Zahl der beobachteten Übertragungen
A11: Beobachtete Übertragungen mit Abweichung (TSM gegen Template) | B11: =IFERROR(COUNTIF('Beobachtung TSM'!$H$2:$H$16,"ja")/(COUNTIF('Beobachtung TSM'!$H$2:$H$16,"ja")+COUNTIF('Beobachtung TSM'!$H$2:$H$16,"nein")),"–") -> –
A12: 2. Fehlerquote (Anteil der Durchläufe mit Fehler im Endergebnis)
B13: alt | C13: neu
A14: Fehlerquote | B14: =IFERROR(COUNTIFS(Durchläufe!$D$2:$D$25,"alt",Durchläufe!$T$2:$T$25,"ja")/(COUNTIFS(Durchläufe!$D$2:$D$25,"alt",Durchläufe!$T$2:$T$25,"ja")+COUNTIFS(Durchläufe!$D$2:$D$25,"alt",Durchläufe!$T$2:$T$25,"nein")),"–") -> – | C14: =IFERROR(COUNTIFS(Durchläufe!$D$2:$D$25,"neu",Durchläufe!$T$2:$T$25,"ja")/(COUNTIFS(Durchläufe!$D$2:$D$25,"neu",Durchläufe!$T$2:$T$25,"ja")+COUNTIFS(Durchläufe!$D$2:$D$25,"neu",Durchläufe!$T$2:$T$25,"nein")),"–") -> –
A16: Wo wurden Fehler abgefangen? (Anzahl)
A17: Stelle | B17: alt | C17: neu
A18: Formular | B18: =COUNTIFS(Fehler!$D$2:$D$199,"alt",Fehler!$H$2:$H$199,A18) -> 0 | C18: =COUNTIFS(Fehler!$D$2:$D$199,"neu",Fehler!$H$2:$H$199,A18) -> 0
A19: Server | B19: =COUNTIFS(Fehler!$D$2:$D$199,"alt",Fehler!$H$2:$H$199,A19) -> 0 | C19: =COUNTIFS(Fehler!$D$2:$D$199,"neu",Fehler!$H$2:$H$199,A19) -> 0
A20: CC bei Prüfung | B20: =COUNTIFS(Fehler!$D$2:$D$199,"alt",Fehler!$H$2:$H$199,A20) -> 0 | C20: =COUNTIFS(Fehler!$D$2:$D$199,"neu",Fehler!$H$2:$H$199,A20) -> 0
A21: AdHoc verworfen | B21: =COUNTIFS(Fehler!$D$2:$D$199,"alt",Fehler!$H$2:$H$199,A21) -> 0 | C21: =COUNTIFS(Fehler!$D$2:$D$199,"neu",Fehler!$H$2:$H$199,A21) -> 0
A22: gar nicht | B22: =COUNTIFS(Fehler!$D$2:$D$199,"alt",Fehler!$H$2:$H$199,A22) -> 0 | C22: =COUNTIFS(Fehler!$D$2:$D$199,"neu",Fehler!$H$2:$H$199,A22) -> 0
A23: Summe | B23: =SUM(B18:B22) -> 0 | C23: =SUM(C18:C22) -> 0
A25: 3. Datenqualität
A26: Dimension | B26: alt | C26: neu
A27: Vollständigkeit (Felder vorhanden) | B27: =IFERROR(COUNTIFS(Datenqualität!$C$2:$C$241,"alt",Datenqualität!$G$2:$G$241,"ja")/(COUNTIFS(Datenqualität!$C$2:$C$241,"alt",Datenqualität!$G$2:$G$241,"ja")+COUNTIFS(Datenqualität!$C$2:$C$241,"alt",Datenqualität!$G$2:$G$241,"nein")),"–") -> – | C27: =IFERROR(COUNTIFS(Datenqualität!$C$2:$C$241,"neu",Datenqualität!$G$2:$G$241,"ja")/(COUNTIFS(Datenqualität!$C$2:$C$241,"neu",Datenqualität!$G$2:$G$241,"ja")+COUNTIFS(Datenqualität!$C$2:$C$241,"neu",Datenqualität!$G$2:$G$241,"nein")),"–") -> –
A28: Korrektheit (Ist = Soll) | B28: =IFERROR(COUNTIFS(Datenqualität!$C$2:$C$241,"alt",Datenqualität!$H$2:$H$241,"ja")/(COUNTIFS(Datenqualität!$C$2:$C$241,"alt",Datenqualität!$H$2:$H$241,"ja")+COUNTIFS(Datenqualität!$C$2:$C$241,"alt",Datenqualität!$H$2:$H$241,"nein")),"–") -> – | C28: =IFERROR(COUNTIFS(Datenqualität!$C$2:$C$241,"neu",Datenqualität!$H$2:$H$241,"ja")/(COUNTIFS(Datenqualität!$C$2:$C$241,"neu",Datenqualität!$H$2:$H$241,"ja")+COUNTIFS(Datenqualität!$C$2:$C$241,"neu",Datenqualität!$H$2:$H$241,"nein")),"–") -> –
A29: Konsistenz (Durchläufe ohne Widerspruch) | B29: =IFERROR(COUNTIFS(Durchläufe!$D$2:$D$25,"alt",Durchläufe!$S$2:$S$25,"ja")/(COUNTIFS(Durchläufe!$D$2:$D$25,"alt",Durchläufe!$S$2:$S$25,"ja")+COUNTIFS(Durchläufe!$D$2:$D$25,"alt",Durchläufe!$S$2:$S$25,"nein")),"–") -> – | C29: =IFERROR(COUNTIFS(Durchläufe!$D$2:$D$25,"neu",Durchläufe!$S$2:$S$25,"ja")/(COUNTIFS(Durchläufe!$D$2:$D$25,"neu",Durchläufe!$S$2:$S$25,"ja")+COUNTIFS(Durchläufe!$D$2:$D$25,"neu",Durchläufe!$S$2:$S$25,"nein")),"–") -> –
A31: 4. Zufriedenheit (Mittelwert, 1 bis 5)
A32: Aussage | B32: alt | C32: neu
A33: 1. Ich konnte die Anfrage ohne Umwege erfassen bzw. prüfen. | B33: =IFERROR(AVERAGEIFS(Befragung!$E$2:$E$49,Befragung!$C$2:$C$49,1),"–") -> – | C33: =IFERROR(AVERAGEIFS(Befragung!$F$2:$F$49,Befragung!$C$2:$C$49,1),"–") -> –
A34: 2. Ich wusste jederzeit, was als Nächstes zu tun ist. | B34: =IFERROR(AVERAGEIFS(Befragung!$E$2:$E$49,Befragung!$C$2:$C$49,2),"–") -> – | C34: =IFERROR(AVERAGEIFS(Befragung!$F$2:$F$49,Befragung!$C$2:$C$49,2),"–") -> –
A35: 3. Das Werkzeug hat sich so verhalten, wie ich es erwartet habe. | B35: =IFERROR(AVERAGEIFS(Befragung!$E$2:$E$49,Befragung!$C$2:$C$49,3),"–") -> – | C35: =IFERROR(AVERAGEIFS(Befragung!$F$2:$F$49,Befragung!$C$2:$C$49,3),"–") -> –
A36: 4. Fehler in den Angaben wurden rechtzeitig und verständlich angezeigt. | B36: =IFERROR(AVERAGEIFS(Befragung!$E$2:$E$49,Befragung!$C$2:$C$49,4),"–") -> – | C36: =IFERROR(AVERAGEIFS(Befragung!$F$2:$F$49,Befragung!$C$2:$C$49,4),"–") -> –
A37: 5. Ich hatte den Ablauf jederzeit unter Kontrolle. | B37: =IFERROR(AVERAGEIFS(Befragung!$E$2:$E$49,Befragung!$C$2:$C$49,5),"–") -> – | C37: =IFERROR(AVERAGEIFS(Befragung!$F$2:$F$49,Befragung!$C$2:$C$49,5),"–") -> –
A38: 6. Ich kann nachvollziehen, was mit einer Anfrage passiert ist. | B38: =IFERROR(AVERAGEIFS(Befragung!$E$2:$E$49,Befragung!$C$2:$C$49,6),"–") -> – | C38: =IFERROR(AVERAGEIFS(Befragung!$F$2:$F$49,Befragung!$C$2:$C$49,6),"–") -> –
A39: 7. Mit diesem Weg würde ich im Alltag gern arbeiten. | B39: =IFERROR(AVERAGEIFS(Befragung!$E$2:$E$49,Befragung!$C$2:$C$49,7),"–") -> – | C39: =IFERROR(AVERAGEIFS(Befragung!$F$2:$F$49,Befragung!$C$2:$C$49,7),"–") -> –
A41: 5. Hochrechnung
A42: Anfragen pro Monat (aus Testdaten) | B42: =IF(Testdaten!B8="","–",Testdaten!B8) -> 256
A43: Ersparnis je Anfrage heute [min] | B43: =IFERROR(B9-D9,"–") -> –
A44: Ersparnis je Anfrage mit Schnittstelle [min] | B44: =IFERROR(B9-C9,"–") -> –
A45: Ersparnis pro Monat heute [h] | B45: =IFERROR(B43*B42/60,"–") -> –
...
